<?xml version="1.0" encoding="UTF-8"?>
<testng-results skipped="0" failed="2" ignored="0" total="3" passed="1">
  <reporter-output>
  </reporter-output>
  <suite name="Suite" duration-ms="67559" started-at="2020-02-15T20:36:58 IST" finished-at="2020-02-15T20:38:05 IST">
    <groups>
    </groups>
    <test name="Test" duration-ms="67559" started-at="2020-02-15T20:36:58 IST" finished-at="2020-02-15T20:38:05 IST">
      <class name="com.home.testcases.Test1">
        <test-method status="PASS" signature="setUp()[pri:0, instance:com.home.testcases.Test1@9660f4e]" name="setUp" is-config="true" duration-ms="111" started-at="2020-02-15T20:36:58 IST" finished-at="2020-02-15T20:36:58 IST">
          <reporter-output>
          </reporter-output>
        </test-method> <!-- setUp -->
        <test-method status="PASS" signature="init()[pri:0, instance:com.home.testcases.Test1@9660f4e]" name="init" duration-ms="11232" started-at="2020-02-15T20:36:58 IST" finished-at="2020-02-15T20:37:09 IST">
          <reporter-output>
          </reporter-output>
        </test-method> <!-- init -->
        <test-method status="PASS" signature="quit()[pri:0, instance:com.home.testcases.Test1@9660f4e]" name="quit" is-config="true" duration-ms="4323" started-at="2020-02-15T20:37:09 IST" finished-at="2020-02-15T20:37:13 IST">
          <reporter-output>
          </reporter-output>
        </test-method> <!-- quit -->
        <test-method status="PASS" signature="quit()[pri:0, instance:com.home.testcases.Test1@9660f4e]" name="quit" is-config="true" duration-ms="133" started-at="2020-02-15T20:37:24 IST" finished-at="2020-02-15T20:37:25 IST">
          <reporter-output>
          </reporter-output>
        </test-method> <!-- quit -->
        <test-method status="FAIL" signature="init1()[pri:0, instance:com.home.testcases.Test1@9660f4e]" name="init1" duration-ms="10690" started-at="2020-02-15T20:37:25 IST" finished-at="2020-02-15T20:37:35 IST">
          <exception class="java.lang.AssertionError">
            <message>
              <![CDATA[did not expect to find [true] but found [false]]]>
            </message>
            <full-stacktrace>
              <![CDATA[java.lang.AssertionError: did not expect to find [true] but found [false]
at org.testng.Assert.fail(Assert.java:97)
at org.testng.Assert.failNotEquals(Assert.java:969)
at org.testng.Assert.assertTrue(Assert.java:43)
at org.testng.Assert.assertTrue(Assert.java:53)
at com.home.testcases.Test1.init1(Test1.java:52)
at sun.reflect.NativeMethodAccessorImpl.invoke0(Native Method)
at sun.reflect.NativeMethodAccessorImpl.invoke(Unknown Source)
at sun.reflect.DelegatingMethodAccessorImpl.invoke(Unknown Source)
at java.lang.reflect.Method.invoke(Unknown Source)
at org.testng.internal.MethodInvocationHelper.invokeMethod(MethodInvocationHelper.java:133)
at org.testng.internal.TestInvoker.invokeMethod(TestInvoker.java:584)
at org.testng.internal.TestInvoker.retryFailed(TestInvoker.java:204)
at org.testng.internal.MethodRunner.runInSequence(MethodRunner.java:58)
at org.testng.internal.TestInvoker$MethodInvocationAgent.invoke(TestInvoker.java:804)
at org.testng.internal.TestInvoker.invokeTestMethods(TestInvoker.java:145)
at org.testng.internal.TestMethodWorker.invokeTestMethods(TestMethodWorker.java:146)
at org.testng.internal.TestMethodWorker.run(TestMethodWorker.java:128)
at java.util.ArrayList.forEach(Unknown Source)
at org.testng.TestRunner.privateRun(TestRunner.java:770)
at org.testng.TestRunner.run(TestRunner.java:591)
at org.testng.SuiteRunner.runTest(SuiteRunner.java:402)
at org.testng.SuiteRunner.runSequentially(SuiteRunner.java:396)
at org.testng.SuiteRunner.privateRun(SuiteRunner.java:355)
at org.testng.SuiteRunner.run(SuiteRunner.java:304)
at org.testng.SuiteRunnerWorker.runSuite(SuiteRunnerWorker.java:53)
at org.testng.SuiteRunnerWorker.run(SuiteRunnerWorker.java:96)
at org.testng.TestNG.runSuitesSequentially(TestNG.java:1180)
at org.testng.TestNG.runSuitesLocally(TestNG.java:1102)
at org.testng.TestNG.runSuites(TestNG.java:1032)
at org.testng.TestNG.run(TestNG.java:1000)
at org.testng.remote.AbstractRemoteTestNG.run(AbstractRemoteTestNG.java:115)
at org.testng.remote.RemoteTestNG.initAndRun(RemoteTestNG.java:251)
at org.testng.remote.RemoteTestNG.main(RemoteTestNG.java:77)
]]>
            </full-stacktrace>
          </exception> <!-- java.lang.AssertionError -->
          <reporter-output>
          </reporter-output>
        </test-method> <!-- init1 -->
        <test-method status="PASS" signature="quit()[pri:0, instance:com.home.testcases.Test1@9660f4e]" name="quit" is-config="true" duration-ms="4318" started-at="2020-02-15T20:37:35 IST" finished-at="2020-02-15T20:37:40 IST">
          <reporter-output>
          </reporter-output>
        </test-method> <!-- quit -->
        <test-method status="PASS" signature="quit()[pri:0, instance:com.home.testcases.Test1@9660f4e]" name="quit" is-config="true" duration-ms="4325" started-at="2020-02-15T20:37:50 IST" finished-at="2020-02-15T20:37:55 IST">
          <reporter-output>
          </reporter-output>
        </test-method> <!-- quit -->
        <test-method status="FAIL" signature="init2()[pri:0, instance:com.home.testcases.Test1@9660f4e]" name="init2" duration-ms="10733" started-at="2020-02-15T20:37:55 IST" finished-at="2020-02-15T20:38:05 IST">
          <exception class="java.lang.AssertionError">
            <message>
              <![CDATA[did not expect to find [true] but found [false]]]>
            </message>
            <full-stacktrace>
              <![CDATA[java.lang.AssertionError: did not expect to find [true] but found [false]
at org.testng.Assert.fail(Assert.java:97)
at org.testng.Assert.failNotEquals(Assert.java:969)
at org.testng.Assert.assertTrue(Assert.java:43)
at org.testng.Assert.assertTrue(Assert.java:53)
at com.home.testcases.Test1.init2(Test1.java:65)
at sun.reflect.NativeMethodAccessorImpl.invoke0(Native Method)
at sun.reflect.NativeMethodAccessorImpl.invoke(Unknown Source)
at sun.reflect.DelegatingMethodAccessorImpl.invoke(Unknown Source)
at java.lang.reflect.Method.invoke(Unknown Source)
at org.testng.internal.MethodInvocationHelper.invokeMethod(MethodInvocationHelper.java:133)
at org.testng.internal.TestInvoker.invokeMethod(TestInvoker.java:584)
at org.testng.internal.TestInvoker.retryFailed(TestInvoker.java:204)
at org.testng.internal.MethodRunner.runInSequence(MethodRunner.java:58)
at org.testng.internal.TestInvoker$MethodInvocationAgent.invoke(TestInvoker.java:804)
at org.testng.internal.TestInvoker.invokeTestMethods(TestInvoker.java:145)
at org.testng.internal.TestMethodWorker.invokeTestMethods(TestMethodWorker.java:146)
at org.testng.internal.TestMethodWorker.run(TestMethodWorker.java:128)
at java.util.ArrayList.forEach(Unknown Source)
at org.testng.TestRunner.privateRun(TestRunner.java:770)
at org.testng.TestRunner.run(TestRunner.java:591)
at org.testng.SuiteRunner.runTest(SuiteRunner.java:402)
at org.testng.SuiteRunner.runSequentially(SuiteRunner.java:396)
at org.testng.SuiteRunner.privateRun(SuiteRunner.java:355)
at org.testng.SuiteRunner.run(SuiteRunner.java:304)
at org.testng.SuiteRunnerWorker.runSuite(SuiteRunnerWorker.java:53)
at org.testng.SuiteRunnerWorker.run(SuiteRunnerWorker.java:96)
at org.testng.TestNG.runSuitesSequentially(TestNG.java:1180)
at org.testng.TestNG.runSuitesLocally(TestNG.java:1102)
at org.testng.TestNG.runSuites(TestNG.java:1032)
at org.testng.TestNG.run(TestNG.java:1000)
at org.testng.remote.AbstractRemoteTestNG.run(AbstractRemoteTestNG.java:115)
at org.testng.remote.RemoteTestNG.initAndRun(RemoteTestNG.java:251)
at org.testng.remote.RemoteTestNG.main(RemoteTestNG.java:77)
]]>
            </full-stacktrace>
          </exception> <!-- java.lang.AssertionError -->
          <reporter-output>
          </reporter-output>
        </test-method> <!-- init2 -->
        <test-method status="PASS" signature="quit()[pri:0, instance:com.home.testcases.Test1@9660f4e]" name="quit" is-config="true" duration-ms="71" started-at="2020-02-15T20:38:05 IST" finished-at="2020-02-15T20:38:05 IST">
          <reporter-output>
          </reporter-output>
        </test-method> <!-- quit -->
      </class> <!-- com.home.testcases.Test1 -->
    </test> <!-- Test -->
  </suite> <!-- Suite -->
</testng-results>
